 * Serving Flask app "search_app" (lazy loading)
 * Environment: production
   WARNING: This is a development server. Do not use it in a production deployment.
   Use a production WSGI server instead.
 * Debug mode: on
 * Running on http://0.0.0.0:9873/ (Press CTRL+C to quit)
 * Restarting with stat
 * Debugger is active!
 * Debugger PIN: 282-056-378
127.0.0.1 - - [15/Sep/2020 05:06:39] "[37mGET / HTTP/1.1[0m" 200 -
 * Serving Flask app "search_app" (lazy loading)
 * Environment: production
   WARNING: This is a development server. Do not use it in a production deployment.
   Use a production WSGI server instead.
 * Debug mode: on
 * Running on http://0.0.0.0:9873/ (Press CTRL+C to quit)
 * Restarting with stat
 * Debugger is active!
 * Debugger PIN: 282-056-378
 * Serving Flask app "search_app" (lazy loading)
 * Environment: production
   WARNING: This is a development server. Do not use it in a production deployment.
   Use a production WSGI server instead.
 * Debug mode: on
 * Running on http://0.0.0.0:9873/ (Press CTRL+C to quit)
 * Restarting with stat
 * Debugger is active!
 * Debugger PIN: 282-056-378
 * Serving Flask app "search_app" (lazy loading)
 * Environment: production
   WARNING: This is a development server. Do not use it in a production deployment.
   Use a production WSGI server instead.
 * Debug mode: on
 * Running on http://0.0.0.0:9873/ (Press CTRL+C to quit)
 * Restarting with stat
 * Debugger is active!
 * Debugger PIN: 282-056-378
127.0.0.1 - - [15/Sep/2020 05:47:09] "[37mGET / HTTP/1.1[0m" 200 -
127.0.0.1 - - [15/Sep/2020 05:47:35] "[35m[1mGET /para_search?query=love HTTP/1.1[0m" 500 -
Traceback (most recent call last):
  File "/usr/local/lib/python3.6/dist-packages/flask/app.py", line 2464, in __call__
    return self.wsgi_app(environ, start_response)
  File "/usr/local/lib/python3.6/dist-packages/flask/app.py", line 2450, in wsgi_app
    response = self.handle_exception(e)
  File "/usr/local/lib/python3.6/dist-packages/flask/app.py", line 1867, in handle_exception
    reraise(exc_type, exc_value, tb)
  File "/usr/local/lib/python3.6/dist-packages/flask/_compat.py", line 39, in reraise
    raise value
  File "/usr/local/lib/python3.6/dist-packages/flask/app.py", line 2447, in wsgi_app
    response = self.full_dispatch_request()
  File "/usr/local/lib/python3.6/dist-packages/flask/app.py", line 1952, in full_dispatch_request
    rv = self.handle_user_exception(e)
  File "/usr/local/lib/python3.6/dist-packages/flask/app.py", line 1821, in handle_user_exception
    reraise(exc_type, exc_value, tb)
  File "/usr/local/lib/python3.6/dist-packages/flask/_compat.py", line 39, in reraise
    raise value
  File "/usr/local/lib/python3.6/dist-packages/flask/app.py", line 1950, in full_dispatch_request
    rv = self.dispatch_request()
  File "/usr/local/lib/python3.6/dist-packages/flask/app.py", line 1936, in dispatch_request
    return self.view_functions[rule.endpoint](**req.view_args)
  File "/home/nhnske/shopee_search/search_app.py", line 65, in para_search
    _id = set(i['_source']['item_itemid'])
TypeError: 'int' object is not iterable
 * Detected change in '/home/nhnske/shopee_search/search_app.py', reloading
 * Restarting with stat
 * Debugger is active!
 * Debugger PIN: 282-056-378
127.0.0.1 - - [15/Sep/2020 05:48:49] "[35m[1mGET /para_search?query=love HTTP/1.1[0m" 500 -
Traceback (most recent call last):
  File "/usr/local/lib/python3.6/dist-packages/flask/app.py", line 2464, in __call__
    return self.wsgi_app(environ, start_response)
  File "/usr/local/lib/python3.6/dist-packages/flask/app.py", line 2450, in wsgi_app
    response = self.handle_exception(e)
  File "/usr/local/lib/python3.6/dist-packages/flask/app.py", line 1867, in handle_exception
    reraise(exc_type, exc_value, tb)
  File "/usr/local/lib/python3.6/dist-packages/flask/_compat.py", line 39, in reraise
    raise value
  File "/usr/local/lib/python3.6/dist-packages/flask/app.py", line 2447, in wsgi_app
    response = self.full_dispatch_request()
  File "/usr/local/lib/python3.6/dist-packages/flask/app.py", line 1952, in full_dispatch_request
    rv = self.handle_user_exception(e)
  File "/usr/local/lib/python3.6/dist-packages/flask/app.py", line 1821, in handle_user_exception
    reraise(exc_type, exc_value, tb)
  File "/usr/local/lib/python3.6/dist-packages/flask/_compat.py", line 39, in reraise
    raise value
  File "/usr/local/lib/python3.6/dist-packages/flask/app.py", line 1950, in full_dispatch_request
    rv = self.dispatch_request()
  File "/usr/local/lib/python3.6/dist-packages/flask/app.py", line 1936, in dispatch_request
    return self.view_functions[rule.endpoint](**req.view_args)
  File "/home/nhnske/shopee_search/search_app.py", line 66, in para_search
    item = saved_data['items_dict'][_id]
TypeError: unhashable type: 'set'
 * Detected change in '/home/nhnske/shopee_search/search_app.py', reloading
 * Restarting with stat
 * Debugger is active!
 * Debugger PIN: 282-056-378
127.0.0.1 - - [15/Sep/2020 05:49:39] "[35m[1mGET /para_search?query=love HTTP/1.1[0m" 500 -
Traceback (most recent call last):
  File "/usr/local/lib/python3.6/dist-packages/flask/app.py", line 2464, in __call__
    return self.wsgi_app(environ, start_response)
  File "/usr/local/lib/python3.6/dist-packages/flask/app.py", line 2450, in wsgi_app
    response = self.handle_exception(e)
  File "/usr/local/lib/python3.6/dist-packages/flask/app.py", line 1867, in handle_exception
    reraise(exc_type, exc_value, tb)
  File "/usr/local/lib/python3.6/dist-packages/flask/_compat.py", line 39, in reraise
    raise value
  File "/usr/local/lib/python3.6/dist-packages/flask/app.py", line 2447, in wsgi_app
    response = self.full_dispatch_request()
  File "/usr/local/lib/python3.6/dist-packages/flask/app.py", line 1952, in full_dispatch_request
    rv = self.handle_user_exception(e)
  File "/usr/local/lib/python3.6/dist-packages/flask/app.py", line 1821, in handle_user_exception
    reraise(exc_type, exc_value, tb)
  File "/usr/local/lib/python3.6/dist-packages/flask/_compat.py", line 39, in reraise
    raise value
  File "/usr/local/lib/python3.6/dist-packages/flask/app.py", line 1950, in full_dispatch_request
    rv = self.dispatch_request()
  File "/usr/local/lib/python3.6/dist-packages/flask/app.py", line 1936, in dispatch_request
    return self.view_functions[rule.endpoint](**req.view_args)
  File "/home/nhnske/shopee_search/search_app.py", line 66, in para_search
    item = saved_data['items_dict'][_id]
KeyError: '(3304837331, 15060)'
 * Detected change in '/home/nhnske/shopee_search/search_app.py', reloading
 * Restarting with stat
 * Debugger is active!
 * Debugger PIN: 282-056-378
127.0.0.1 - - [15/Sep/2020 05:50:16] "[35m[1mGET /para_search?query=love HTTP/1.1[0m" 500 -
Traceback (most recent call last):
  File "/usr/local/lib/python3.6/dist-packages/flask/app.py", line 2464, in __call__
    return self.wsgi_app(environ, start_response)
  File "/usr/local/lib/python3.6/dist-packages/flask/app.py", line 2450, in wsgi_app
    response = self.handle_exception(e)
  File "/usr/local/lib/python3.6/dist-packages/flask/app.py", line 1867, in handle_exception
    reraise(exc_type, exc_value, tb)
  File "/usr/local/lib/python3.6/dist-packages/flask/_compat.py", line 39, in reraise
    raise value
  File "/usr/local/lib/python3.6/dist-packages/flask/app.py", line 2447, in wsgi_app
    response = self.full_dispatch_request()
  File "/usr/local/lib/python3.6/dist-packages/flask/app.py", line 1952, in full_dispatch_request
    rv = self.handle_user_exception(e)
  File "/usr/local/lib/python3.6/dist-packages/flask/app.py", line 1821, in handle_user_exception
    reraise(exc_type, exc_value, tb)
  File "/usr/local/lib/python3.6/dist-packages/flask/_compat.py", line 39, in reraise
    raise value
  File "/usr/local/lib/python3.6/dist-packages/flask/app.py", line 1950, in full_dispatch_request
    rv = self.dispatch_request()
  File "/usr/local/lib/python3.6/dist-packages/flask/app.py", line 1936, in dispatch_request
    return self.view_functions[rule.endpoint](**req.view_args)
  File "/home/nhnske/shopee_search/search_app.py", line 67, in para_search
    item = saved_data['items_dict'][_id]
KeyError: '(3304837331, 15060)'
127.0.0.1 - - [15/Sep/2020 05:50:33] "[35m[1mGET /para_search?query=love HTTP/1.1[0m" 500 -
Traceback (most recent call last):
  File "/usr/local/lib/python3.6/dist-packages/flask/app.py", line 2464, in __call__
    return self.wsgi_app(environ, start_response)
  File "/usr/local/lib/python3.6/dist-packages/flask/app.py", line 2450, in wsgi_app
    response = self.handle_exception(e)
  File "/usr/local/lib/python3.6/dist-packages/flask/app.py", line 1867, in handle_exception
    reraise(exc_type, exc_value, tb)
  File "/usr/local/lib/python3.6/dist-packages/flask/_compat.py", line 39, in reraise
    raise value
  File "/usr/local/lib/python3.6/dist-packages/flask/app.py", line 2447, in wsgi_app
    response = self.full_dispatch_request()
  File "/usr/local/lib/python3.6/dist-packages/flask/app.py", line 1952, in full_dispatch_request
    rv = self.handle_user_exception(e)
  File "/usr/local/lib/python3.6/dist-packages/flask/app.py", line 1821, in handle_user_exception
    reraise(exc_type, exc_value, tb)
  File "/usr/local/lib/python3.6/dist-packages/flask/_compat.py", line 39, in reraise
    raise value
  File "/usr/local/lib/python3.6/dist-packages/flask/app.py", line 1950, in full_dispatch_request
    rv = self.dispatch_request()
  File "/usr/local/lib/python3.6/dist-packages/flask/app.py", line 1936, in dispatch_request
    return self.view_functions[rule.endpoint](**req.view_args)
  File "/home/nhnske/shopee_search/search_app.py", line 67, in para_search
    item = saved_data['items_dict'][_id]
KeyError: '(3304837331, 15060)'
127.0.0.1 - - [15/Sep/2020 05:53:20] "[35m[1mGET /para_search?query=love HTTP/1.1[0m" 500 -
Traceback (most recent call last):
  File "/usr/local/lib/python3.6/dist-packages/flask/app.py", line 2464, in __call__
    return self.wsgi_app(environ, start_response)
  File "/usr/local/lib/python3.6/dist-packages/flask/app.py", line 2450, in wsgi_app
    response = self.handle_exception(e)
  File "/usr/local/lib/python3.6/dist-packages/flask/app.py", line 1867, in handle_exception
    reraise(exc_type, exc_value, tb)
  File "/usr/local/lib/python3.6/dist-packages/flask/_compat.py", line 39, in reraise
    raise value
  File "/usr/local/lib/python3.6/dist-packages/flask/app.py", line 2447, in wsgi_app
    response = self.full_dispatch_request()
  File "/usr/local/lib/python3.6/dist-packages/flask/app.py", line 1952, in full_dispatch_request
    rv = self.handle_user_exception(e)
  File "/usr/local/lib/python3.6/dist-packages/flask/app.py", line 1821, in handle_user_exception
    reraise(exc_type, exc_value, tb)
  File "/usr/local/lib/python3.6/dist-packages/flask/_compat.py", line 39, in reraise
    raise value
  File "/usr/local/lib/python3.6/dist-packages/flask/app.py", line 1950, in full_dispatch_request
    rv = self.dispatch_request()
  File "/usr/local/lib/python3.6/dist-packages/flask/app.py", line 1936, in dispatch_request
    return self.view_functions[rule.endpoint](**req.view_args)
  File "/home/nhnske/shopee_search/search_app.py", line 67, in para_search
    item = saved_data['items_dict'][_id]
KeyError: '(3304837331, 15060)'
 * Detected change in '/home/nhnske/shopee_search/search_app.py', reloading
{'4', ')', ' ', '8', '6', '3', '1', '7', '(', '5', '0', ','}
{'4', ')', ' ', '8', '6', '3', '1', '7', '(', '5', '0', ','}
{'4', ')', ' ', '8', '6', '3', '1', '7', '(', '5', '0', ','}
 * Restarting with stat
 * Debugger is active!
 * Debugger PIN: 282-056-378
127.0.0.1 - - [15/Sep/2020 05:53:29] "[37mGET /para_search?query=love HTTP/1.1[0m" 200 -
127.0.0.1 - - [15/Sep/2020 06:17:35] "[37mGET / HTTP/1.1[0m" 200 -
127.0.0.1 - - [15/Sep/2020 06:17:47] "[37mGET /para_search?query=love HTTP/1.1[0m" 200 -
 * Detected change in '/home/nhnske/shopee_search/search_app.py', reloading
 * Restarting with stat
 * Debugger is active!
 * Debugger PIN: 282-056-378
127.0.0.1 - - [15/Sep/2020 06:25:56] "[35m[1mGET /para_search?query=love HTTP/1.1[0m" 500 -
Traceback (most recent call last):
  File "/usr/local/lib/python3.6/dist-packages/flask/app.py", line 2464, in __call__
    return self.wsgi_app(environ, start_response)
  File "/usr/local/lib/python3.6/dist-packages/flask/app.py", line 2450, in wsgi_app
    response = self.handle_exception(e)
  File "/usr/local/lib/python3.6/dist-packages/flask/app.py", line 1867, in handle_exception
    reraise(exc_type, exc_value, tb)
  File "/usr/local/lib/python3.6/dist-packages/flask/_compat.py", line 39, in reraise
    raise value
  File "/usr/local/lib/python3.6/dist-packages/flask/app.py", line 2447, in wsgi_app
    response = self.full_dispatch_request()
  File "/usr/local/lib/python3.6/dist-packages/flask/app.py", line 1952, in full_dispatch_request
    rv = self.handle_user_exception(e)
  File "/usr/local/lib/python3.6/dist-packages/flask/app.py", line 1821, in handle_user_exception
    reraise(exc_type, exc_value, tb)
  File "/usr/local/lib/python3.6/dist-packages/flask/_compat.py", line 39, in reraise
    raise value
  File "/usr/local/lib/python3.6/dist-packages/flask/app.py", line 1950, in full_dispatch_request
    rv = self.dispatch_request()
  File "/usr/local/lib/python3.6/dist-packages/flask/app.py", line 1936, in dispatch_request
    return self.view_functions[rule.endpoint](**req.view_args)
  File "/home/nhnske/shopee_search/search_app.py", line 68, in para_search
    item_filtered = {item['item'][key] for key in keys if key in item['item']}
  File "/home/nhnske/shopee_search/search_app.py", line 68, in <setcomp>
    item_filtered = {item['item'][key] for key in keys if key in item['item']}
TypeError: unhashable type: 'list'
59.153.226.45 - - [15/Sep/2020 06:26:35] "[35m[1mGET /para_search?query=%22quan%20ao%22&order=desc&page=0&sortBy=sales/ctime HTTP/1.1[0m" 500 -
Traceback (most recent call last):
  File "/usr/local/lib/python3.6/dist-packages/flask/app.py", line 2464, in __call__
    return self.wsgi_app(environ, start_response)
  File "/usr/local/lib/python3.6/dist-packages/flask/app.py", line 2450, in wsgi_app
    response = self.handle_exception(e)
  File "/usr/local/lib/python3.6/dist-packages/flask/app.py", line 1867, in handle_exception
    reraise(exc_type, exc_value, tb)
  File "/usr/local/lib/python3.6/dist-packages/flask/_compat.py", line 39, in reraise
    raise value
  File "/usr/local/lib/python3.6/dist-packages/flask/app.py", line 2447, in wsgi_app
    response = self.full_dispatch_request()
  File "/usr/local/lib/python3.6/dist-packages/flask/app.py", line 1952, in full_dispatch_request
    rv = self.handle_user_exception(e)
  File "/usr/local/lib/python3.6/dist-packages/flask/app.py", line 1821, in handle_user_exception
    reraise(exc_type, exc_value, tb)
  File "/usr/local/lib/python3.6/dist-packages/flask/_compat.py", line 39, in reraise
    raise value
  File "/usr/local/lib/python3.6/dist-packages/flask/app.py", line 1950, in full_dispatch_request
    rv = self.dispatch_request()
  File "/usr/local/lib/python3.6/dist-packages/flask/app.py", line 1936, in dispatch_request
    return self.view_functions[rule.endpoint](**req.view_args)
  File "/home/nhnske/shopee_search/search_app.py", line 68, in para_search
    item_filtered = {item['item'][key] for key in keys if key in item['item']}
  File "/home/nhnske/shopee_search/search_app.py", line 68, in <setcomp>
    item_filtered = {item['item'][key] for key in keys if key in item['item']}
TypeError: unhashable type: 'list'
59.153.226.45 - - [15/Sep/2020 06:26:41] "[33mGET /para_search/?query=%22quan%20ao%22&order=desc&page=0&sortBy=sales/ctime HTTP/1.1[0m" 404 -
 * Detected change in '/home/nhnske/shopee_search/search_app.py', reloading
 * Restarting with stat
 * Debugger is active!
 * Debugger PIN: 282-056-378
127.0.0.1 - - [15/Sep/2020 06:26:46] "[35m[1mGET /para_search?query=love HTTP/1.1[0m" 500 -
Traceback (most recent call last):
  File "/usr/local/lib/python3.6/dist-packages/flask/app.py", line 2464, in __call__
    return self.wsgi_app(environ, start_response)
  File "/usr/local/lib/python3.6/dist-packages/flask/app.py", line 2450, in wsgi_app
    response = self.handle_exception(e)
  File "/usr/local/lib/python3.6/dist-packages/flask/app.py", line 1867, in handle_exception
    reraise(exc_type, exc_value, tb)
  File "/usr/local/lib/python3.6/dist-packages/flask/_compat.py", line 39, in reraise
    raise value
  File "/usr/local/lib/python3.6/dist-packages/flask/app.py", line 2447, in wsgi_app
    response = self.full_dispatch_request()
  File "/usr/local/lib/python3.6/dist-packages/flask/app.py", line 1952, in full_dispatch_request
    rv = self.handle_user_exception(e)
  File "/usr/local/lib/python3.6/dist-packages/flask/app.py", line 1821, in handle_user_exception
    reraise(exc_type, exc_value, tb)
  File "/usr/local/lib/python3.6/dist-packages/flask/_compat.py", line 39, in reraise
    raise value
  File "/usr/local/lib/python3.6/dist-packages/flask/app.py", line 1950, in full_dispatch_request
    rv = self.dispatch_request()
  File "/usr/local/lib/python3.6/dist-packages/flask/app.py", line 1936, in dispatch_request
    return self.view_functions[rule.endpoint](**req.view_args)
  File "/home/nhnske/shopee_search/search_app.py", line 68, in para_search
    item_filtered = {item['item'][key] for key in keys if key in item['item']}
  File "/home/nhnske/shopee_search/search_app.py", line 68, in <setcomp>
    item_filtered = {item['item'][key] for key in keys if key in item['item']}
TypeError: unhashable type: 'list'
59.153.226.45 - - [15/Sep/2020 06:26:46] "[35m[1mGET /para_search?query=%22quan%20ao%22&order=desc&page=0&sortBy=sales/ctime HTTP/1.1[0m" 500 -
Traceback (most recent call last):
  File "/usr/local/lib/python3.6/dist-packages/flask/app.py", line 2464, in __call__
    return self.wsgi_app(environ, start_response)
  File "/usr/local/lib/python3.6/dist-packages/flask/app.py", line 2450, in wsgi_app
    response = self.handle_exception(e)
  File "/usr/local/lib/python3.6/dist-packages/flask/app.py", line 1867, in handle_exception
    reraise(exc_type, exc_value, tb)
  File "/usr/local/lib/python3.6/dist-packages/flask/_compat.py", line 39, in reraise
    raise value
  File "/usr/local/lib/python3.6/dist-packages/flask/app.py", line 2447, in wsgi_app
    response = self.full_dispatch_request()
  File "/usr/local/lib/python3.6/dist-packages/flask/app.py", line 1952, in full_dispatch_request
    rv = self.handle_user_exception(e)
  File "/usr/local/lib/python3.6/dist-packages/flask/app.py", line 1821, in handle_user_exception
    reraise(exc_type, exc_value, tb)
  File "/usr/local/lib/python3.6/dist-packages/flask/_compat.py", line 39, in reraise
    raise value
  File "/usr/local/lib/python3.6/dist-packages/flask/app.py", line 1950, in full_dispatch_request
    rv = self.dispatch_request()
  File "/usr/local/lib/python3.6/dist-packages/flask/app.py", line 1936, in dispatch_request
    return self.view_functions[rule.endpoint](**req.view_args)
  File "/home/nhnske/shopee_search/search_app.py", line 68, in para_search
    item_filtered = {item['item'][key] for key in keys if key in item['item']}
  File "/home/nhnske/shopee_search/search_app.py", line 68, in <setcomp>
    item_filtered = {item['item'][key] for key in keys if key in item['item']}
TypeError: unhashable type: 'list'
59.153.226.45 - - [15/Sep/2020 06:26:52] "[35m[1mGET /para_search?query=%22quần%20áo%22&order=desc&page=0&sortBy=sales/ctime HTTP/1.1[0m" 500 -
Traceback (most recent call last):
  File "/usr/local/lib/python3.6/dist-packages/flask/app.py", line 2464, in __call__
    return self.wsgi_app(environ, start_response)
  File "/usr/local/lib/python3.6/dist-packages/flask/app.py", line 2450, in wsgi_app
    response = self.handle_exception(e)
  File "/usr/local/lib/python3.6/dist-packages/flask/app.py", line 1867, in handle_exception
    reraise(exc_type, exc_value, tb)
  File "/usr/local/lib/python3.6/dist-packages/flask/_compat.py", line 39, in reraise
    raise value
  File "/usr/local/lib/python3.6/dist-packages/flask/app.py", line 2447, in wsgi_app
    response = self.full_dispatch_request()
  File "/usr/local/lib/python3.6/dist-packages/flask/app.py", line 1952, in full_dispatch_request
    rv = self.handle_user_exception(e)
  File "/usr/local/lib/python3.6/dist-packages/flask/app.py", line 1821, in handle_user_exception
    reraise(exc_type, exc_value, tb)
  File "/usr/local/lib/python3.6/dist-packages/flask/_compat.py", line 39, in reraise
    raise value
  File "/usr/local/lib/python3.6/dist-packages/flask/app.py", line 1950, in full_dispatch_request
    rv = self.dispatch_request()
  File "/usr/local/lib/python3.6/dist-packages/flask/app.py", line 1936, in dispatch_request
    return self.view_functions[rule.endpoint](**req.view_args)
  File "/home/nhnske/shopee_search/search_app.py", line 68, in para_search
    item_filtered = {item['item'][key] for key in keys if key in item['item']}
  File "/home/nhnske/shopee_search/search_app.py", line 68, in <setcomp>
    item_filtered = {item['item'][key] for key in keys if key in item['item']}
TypeError: unhashable type: 'list'
 * Detected change in '/home/nhnske/shopee_search/search_app.py', reloading
 * Restarting with stat
 * Debugger is active!
 * Debugger PIN: 282-056-378
127.0.0.1 - - [15/Sep/2020 06:32:22] "[37mGET /para_search?query=love HTTP/1.1[0m" 200 -
 * Detected change in '/home/nhnske/shopee_search/search_app.py', reloading
 * Restarting with stat
 * Debugger is active!
 * Debugger PIN: 282-056-378
127.0.0.1 - - [15/Sep/2020 06:33:09] "[37mGET /para_search?query=love HTTP/1.1[0m" 200 -
 * Detected change in '/home/nhnske/shopee_search/search_app.py', reloading
 * Restarting with stat
 * Debugger is active!
 * Debugger PIN: 282-056-378
127.0.0.1 - - [15/Sep/2020 07:07:25] "[35m[1mGET /para_search?query=love HTTP/1.1[0m" 500 -
Traceback (most recent call last):
  File "/usr/local/lib/python3.6/dist-packages/flask/app.py", line 2464, in __call__
    return self.wsgi_app(environ, start_response)
  File "/usr/local/lib/python3.6/dist-packages/flask/app.py", line 2450, in wsgi_app
    response = self.handle_exception(e)
  File "/usr/local/lib/python3.6/dist-packages/flask/app.py", line 1867, in handle_exception
    reraise(exc_type, exc_value, tb)
  File "/usr/local/lib/python3.6/dist-packages/flask/_compat.py", line 39, in reraise
    raise value
  File "/usr/local/lib/python3.6/dist-packages/flask/app.py", line 2447, in wsgi_app
    response = self.full_dispatch_request()
  File "/usr/local/lib/python3.6/dist-packages/flask/app.py", line 1953, in full_dispatch_request
    return self.finalize_request(rv)
  File "/usr/local/lib/python3.6/dist-packages/flask/app.py", line 1968, in finalize_request
    response = self.make_response(rv)
  File "/usr/local/lib/python3.6/dist-packages/flask/app.py", line 2112, in make_response
    rv = jsonify(rv)
  File "/usr/local/lib/python3.6/dist-packages/flask/json/__init__.py", line 370, in jsonify
    dumps(data, indent=indent, separators=separators) + "\n",
  File "/usr/local/lib/python3.6/dist-packages/flask/json/__init__.py", line 211, in dumps
    rv = _json.dumps(obj, **kwargs)
  File "/usr/lib/python3.6/json/__init__.py", line 238, in dumps
    **kw).encode(obj)
  File "/usr/lib/python3.6/json/encoder.py", line 201, in encode
    chunks = list(chunks)
  File "/usr/lib/python3.6/json/encoder.py", line 430, in _iterencode
    yield from _iterencode_dict(o, _current_indent_level)
  File "/usr/lib/python3.6/json/encoder.py", line 404, in _iterencode_dict
    yield from chunks
  File "/usr/lib/python3.6/json/encoder.py", line 325, in _iterencode_list
    yield from chunks
  File "/usr/lib/python3.6/json/encoder.py", line 437, in _iterencode
    o = _default(o)
  File "/usr/local/lib/python3.6/dist-packages/flask/json/__init__.py", line 100, in default
    return _json.JSONEncoder.default(self, o)
  File "/usr/lib/python3.6/json/encoder.py", line 180, in default
    o.__class__.__name__)
TypeError: Object of type 'type' is not JSON serializable
127.0.0.1 - - [15/Sep/2020 07:07:39] "[35m[1mGET /para_search?query=love HTTP/1.1[0m" 500 -
Traceback (most recent call last):
  File "/usr/local/lib/python3.6/dist-packages/flask/app.py", line 2464, in __call__
    return self.wsgi_app(environ, start_response)
  File "/usr/local/lib/python3.6/dist-packages/flask/app.py", line 2450, in wsgi_app
    response = self.handle_exception(e)
  File "/usr/local/lib/python3.6/dist-packages/flask/app.py", line 1867, in handle_exception
    reraise(exc_type, exc_value, tb)
  File "/usr/local/lib/python3.6/dist-packages/flask/_compat.py", line 39, in reraise
    raise value
  File "/usr/local/lib/python3.6/dist-packages/flask/app.py", line 2447, in wsgi_app
    response = self.full_dispatch_request()
  File "/usr/local/lib/python3.6/dist-packages/flask/app.py", line 1953, in full_dispatch_request
    return self.finalize_request(rv)
  File "/usr/local/lib/python3.6/dist-packages/flask/app.py", line 1968, in finalize_request
    response = self.make_response(rv)
  File "/usr/local/lib/python3.6/dist-packages/flask/app.py", line 2112, in make_response
    rv = jsonify(rv)
  File "/usr/local/lib/python3.6/dist-packages/flask/json/__init__.py", line 370, in jsonify
    dumps(data, indent=indent, separators=separators) + "\n",
  File "/usr/local/lib/python3.6/dist-packages/flask/json/__init__.py", line 211, in dumps
    rv = _json.dumps(obj, **kwargs)
  File "/usr/lib/python3.6/json/__init__.py", line 238, in dumps
    **kw).encode(obj)
  File "/usr/lib/python3.6/json/encoder.py", line 201, in encode
    chunks = list(chunks)
  File "/usr/lib/python3.6/json/encoder.py", line 430, in _iterencode
    yield from _iterencode_dict(o, _current_indent_level)
  File "/usr/lib/python3.6/json/encoder.py", line 404, in _iterencode_dict
    yield from chunks
  File "/usr/lib/python3.6/json/encoder.py", line 325, in _iterencode_list
    yield from chunks
  File "/usr/lib/python3.6/json/encoder.py", line 437, in _iterencode
    o = _default(o)
  File "/usr/local/lib/python3.6/dist-packages/flask/json/__init__.py", line 100, in default
    return _json.JSONEncoder.default(self, o)
  File "/usr/lib/python3.6/json/encoder.py", line 180, in default
    o.__class__.__name__)
TypeError: Object of type 'type' is not JSON serializable
 * Detected change in '/home/nhnske/shopee_search/search_app.py', reloading
 * Restarting with stat
 * Debugger is active!
 * Debugger PIN: 282-056-378
127.0.0.1 - - [15/Sep/2020 07:08:13] "[37mGET /para_search?query=love HTTP/1.1[0m" 200 -
 * Detected change in '/home/nhnske/shopee_search/search_app.py', reloading
 * Restarting with stat
 * Debugger is active!
 * Debugger PIN: 282-056-378
127.0.0.1 - - [15/Sep/2020 07:09:21] "[37mGET /para_search?query=love HTTP/1.1[0m" 200 -
59.153.226.45 - - [15/Sep/2020 07:10:31] "[37mGET /para_search?query=%22quần%20áo%22&order=desc&page=0&sortBy=sales/ctime HTTP/1.1[0m" 200 -
59.153.226.45 - - [15/Sep/2020 14:38:07] "[37mGET / HTTP/1.1[0m" 200 -
59.153.226.45 - - [15/Sep/2020 14:38:12] "[37mPOST / HTTP/1.1[0m" 200 -
